See https://www.zotero.org/support/dev/web_api/v3/streaming_api

michael@acer:~/dharma> python3 -m websockets 'wss://stream.zotero.org'
Connected to wss://stream.zotero.org.
< {"event":"connected","retry":10000}

{
   "action": "createSubscriptions",
   "subscriptions": [
      {
         "apiKey": "abcdefghijklmn1234567890"
      }
   ]
}

{
   "action": "deleteSubscriptions",
   "subscriptions": [
      {
         "apiKey": "abcdefghijklmn1234567890"
      }
   ]
}

abcdefghijklmn1234567890
ojTBU4SxEQ4L0OqUhFVyImjq



python3 -m websockets 'wss://stream.zotero.org'
Connected to wss://stream.zotero.org.
< {"event":"connected","retry":10000}
> {"action": "createSubscriptions", "subscriptions": [{"topics": ["/groups/5060750"]}]}
> {"action": "createSubscriptions", "subscriptions": [{"topics": ["/groups/5060750"]}]}Exception in thread Thread-2 (print_incoming_messages):
Traceback (most recent call last):
  File "/usr/lib64/python3.11/threading.py", line 1038, in _bootstrap_inner
    self.run()
  File "/usr/lib64/python3.11/threading.py", line 975, in run
    self._target(*self._args, **self._kwargs)
  File "/usr/lib64/python3.11/site-packages/websockets/__main__.py", line 84, in print_incoming_messages
    for message in websocket:
  File "/usr/lib64/python3.11/site-packages/websockets/sync/connection.py", line 162, in __iter__
    yield self.recv()
          ^^^^^^^^^^^
  File "/usr/lib64/python3.11/site-packages/websockets/sync/connection.py", line 201, in recv
    raise self.protocol.close_exc from self.recv_events_exc
websockets.exceptions.ConnectionClosedError: received 4400 (private use) Message not provided; then sent 4400 (private use) Message not provided

{"action": "createSubscriptions", "subscriptions": [{"apiKey": "ojTBU4SxEQ4L0OqUhFVyImjq", "topics": ["/groups/5060750"]}]}
